ERROR:root:Не удалось получить токен для доступа к API Avito.
ERROR:root:Некорректный ответ от API Avito: {}
INFO:django.utils.autoreload:C:\Users\kolup\AvitoBot-master\avito_bot\avito_bot\settings.py changed, reloading.
INFO:root:Новый токен получен: None
INFO:root:Новый токен получен: None
INFO:root:Новый токен получен: None
INFO:root:Новый токен получен: None
INFO:root:Новый токен получен: None
INFO:root:Новый токен получен: None
INFO:root:Новый токен получен: None
INFO:root:Новый токен получен: None
INFO:root:Новый токен получен: None
ERROR:django.request:Internal Server Error: /
Traceback (most recent call last):
  File "C:\Users\kolup\business_project\.venv\Lib\site-packages\django\core\handlers\exception.py", line 55, in inner
    response = get_response(request)
               ^^^^^^^^^^^^^^^^^^^^^
  File "C:\Users\kolup\business_project\.venv\Lib\site-packages\django\core\handlers\base.py", line 197, in _get_response
    response = wrapped_callback(request, *callback_args, **callback_kwargs)
               ^^^^^^^^^^^^^^^^^^^^^^^^^^^^^^^^^^^^^^^^^^^^^^^^^^^^^^^^^^^^
  File "C:\Users\kolup\AvitoBot-master\avito_bot\bot\views.py", line 15, in index
    if keyword_form.is_valid() and message_form.is_valid():
                                   ^^^^^^^^^^^^^^^^^^^^^
AttributeError: 'Message' object has no attribute 'is_valid'
ERROR:django.server:"POST / HTTP/1.1" 500 73139
INFO:root:Новый токен получен: None
INFO:root:Новый токен получен: None
