
ERROR 2024-09-14 22:12:59,296 log Internal Server Error: /
Traceback (most recent call last):
  File "C:\Users\kolup\business_project\.venv\Lib\site-packages\django\core\handlers\exception.py", line 55, in inner
    response = get_response(request)
               ^^^^^^^^^^^^^^^^^^^^^
  File "C:\Users\kolup\business_project\.venv\Lib\site-packages\django\core\handlers\base.py", line 197, in _get_response
    response = wrapped_callback(request, *callback_args, **callback_kwargs)
               ^^^^^^^^^^^^^^^^^^^^^^^^^^^^^^^^^^^^^^^^^^^^^^^^^^^^^^^^^^^^
  File "C:\Users\kolup\AvitoBot-master\avito_bot\bot\views.py", line 42, in index
    ensure_valid_token(request)
    ^^^^^^^^^^^^^^^^^^
NameError: name 'ensure_valid_token' is not defined
ERROR 2024-09-16 15:35:47,827 log Internal Server Error: /
Traceback (most recent call last):
  File "C:\Users\kolup\business_project\.venv\Lib\site-packages\django\core\handlers\exception.py", line 55, in inner
    response = get_response(request)
               ^^^^^^^^^^^^^^^^^^^^^
  File "C:\Users\kolup\business_project\.venv\Lib\site-packages\django\core\handlers\base.py", line 197, in _get_response
    response = wrapped_callback(request, *callback_args, **callback_kwargs)
               ^^^^^^^^^^^^^^^^^^^^^^^^^^^^^^^^^^^^^^^^^^^^^^^^^^^^^^^^^^^^
  File "C:\Users\kolup\AvitoBot-master\avito_bot\bot\views.py", line 75, in index
    for ad in ads:
TypeError: 'coroutine' object is not iterable
